100%|█████████████████████████████████████████████████████████████████████████████████████████████████████████████████████████████████| 4/4 [00:05<00:00,  1.44s/it]
 OptLR: 0.000050, LR: 0.000500, Acc: 51.0000, Loss: 0.7289
**** Val accuracy: 87.50. ****
100%|█████████████████████████████████████████████████████████████████████████████████████████████████████████████████████████████████| 4/4 [00:01<00:00,  3.31it/s]

 OptLR: 0.000090, LR: 0.000500, Acc: 50.0000, Loss: 0.7438
**** Val accuracy: 75.00. ****
100%|█████████████████████████████████████████████████████████████████████████████████████████████████████████████████████████████████| 4/4 [00:01<00:00,  3.32it/s]

 OptLR: 0.000130, LR: 0.000500, Acc: 50.0000, Loss: 0.6828
**** Val accuracy: 62.50. ****
100%|█████████████████████████████████████████████████████████████████████████████████████████████████████████████████████████████████| 4/4 [00:01<00:00,  3.32it/s]

 OptLR: 0.000170, LR: 0.000500, Acc: 54.0000, Loss: 0.7140
**** Val accuracy: 62.50. ****
  0%|                                                                                                                                         | 0/4 [00:00<?, ?it/s]Exception ignored in: <function _releaseLock at 0x7f92ac5d1000>
Traceback (most recent call last):
  File "/opt/sw/arch/easybuild/2022b/software/Python/3.10.8-GCCcore-12.2.0/lib/python3.10/logging/__init__.py", line 228, in _releaseLock
    def _releaseLock():
KeyboardInterrupt:
  0%|                                                                                                                                         | 0/4 [00:05<?, ?it/s]
Traceback (most recent call last):
  File "/CECI/proj/medresyst/histo_cyto/env/tim/lib/python3.10/site-packages/torch/utils/data/dataloader.py", line 1132, in _try_get_data
    data = self._data_queue.get(timeout=timeout)
  File "/opt/sw/arch/easybuild/2022b/software/Python/3.10.8-GCCcore-12.2.0/lib/python3.10/queue.py", line 179, in get
    raise Empty
_queue.Empty

The above exception was the direct cause of the following exception:

Traceback (most recent call last):
  File "/CECI/proj/medresyst/manon/US/codes/Cytology-fine-tuning/main.py", line 325, in <module>
    main()
  File "/CECI/proj/medresyst/manon/US/codes/Cytology-fine-tuning/main.py", line 310, in main
    run_uni_lora(
  File "/CECI/proj/medresyst/manon/US/codes/Cytology-fine-tuning/lora.py", line 352, in run_uni_lora
    for i, (images, target) in enumerate(tqdm(train_loader)):
  File "/CECI/proj/medresyst/histo_cyto/env/tim/lib/python3.10/site-packages/tqdm/std.py", line 1181, in __iter__
    for obj in iterable:
  File "/CECI/proj/medresyst/histo_cyto/env/tim/lib/python3.10/site-packages/torch/utils/data/dataloader.py", line 633, in __next__
    data = self._next_data()
  File "/CECI/proj/medresyst/histo_cyto/env/tim/lib/python3.10/site-packages/torch/utils/data/dataloader.py", line 1328, in _next_data
    idx, data = self._get_data()
  File "/CECI/proj/medresyst/histo_cyto/env/tim/lib/python3.10/site-packages/torch/utils/data/dataloader.py", line 1284, in _get_data
    success, data = self._try_get_data()
  File "/CECI/proj/medresyst/histo_cyto/env/tim/lib/python3.10/site-packages/torch/utils/data/dataloader.py", line 1145, in _try_get_data
    raise RuntimeError('DataLoader worker (pid(s) {}) exited unexpectedly'.format(pids_str)) from e
RuntimeError: DataLoader worker (pid(s) 1307976) exited unexpectedly
