100%|██████████| 3/3 [00:02<00:00,  1.15it/s]
 OptLR: 0.000008, LR: 0.000100, Acc: 34.3750, Loss: 1.1629
Traceback (most recent call last):
  File "/CECI/proj/medresyst/histo_cyto/env/tim/lib/python3.10/site-packages/transformers/feature_extraction_utils.py", line 93, in __getattr__
    return self.data[item]
KeyError: 'cuda'

During handling of the above exception, another exception occurred:

Traceback (most recent call last):
  File "/CECI/proj/medresyst/manon/US/codes/Cytology-fine-tuning/main.py", line 325, in <module>
    main()
  File "/CECI/proj/medresyst/manon/US/codes/Cytology-fine-tuning/main.py", line 310, in main
    run_uni_lora(
  File "/CECI/proj/medresyst/manon/US/codes/Cytology-fine-tuning/lora.py", line 394, in run_uni_lora
    acc_val, loss_val = evaluate_lora_uni(args, clip_model_, val_loader)
  File "/CECI/proj/medresyst/manon/US/codes/Cytology-fine-tuning/lora.py", line 242, in evaluate_lora_uni
    images, target = images.cuda(), target.cuda()
  File "/CECI/proj/medresyst/histo_cyto/env/tim/lib/python3.10/site-packages/transformers/feature_extraction_utils.py", line 95, in __getattr__
    raise AttributeError
AttributeError
